Workbook
Name NativeTimeline_Date: #N/A
Name Slicer_Category: #N/A
Name Slicer_Customer_Segment: #N/A
Name Slicer_Payment_Method: #N/A
Name Slicer_Region: #N/A

Sheet Instruction
A1: Project Title
A3: Customer Transaction Analysis Dashboard using Microsoft Excel
A7: Project Objective
A9: The objective of this project is to analyze customer transaction data using Microsoft Excel. The project demonstrates data cleaning, data analysis, Pivot Tables, Pivot Charts, Dashboard creation, and business insights for better decision-making.
A13: Software Used
A15: Microsoft Excel (Old Version Compatible)
A16: Excel Pivot Tables
A17: Pivot Charts
A18: Data Analysis ToolPak
A19: Goal Seek
A20: Conditional Formatting
A24: Project Workflow
... A163: This project demonstrates practical use of Microsoft Excel for business data analysis and dashboard reporting. It combines formulas, Pivot Tables, charts, and interactive filters to convert raw transaction data into meaningful insights.

Sheet Raw_Data
A1: Transaction_ID | B1: Date | C1: Customer_ID | D1: Customer_Name | E1: Product_ID | F1: Product_Name | G1: Category | H1: Quantity | I1: Unit_Price | J1: Payment_Method | K1: Region | L1: Customer_Segment | M1: Customer_Since | N1: Total_Amount | O1: Month | P1: Year | Q1: Customer Age Days | R1: Customer Tenure | S1: Transaction Month End | T1: High Value Customer | U1: Timestamp
A2: TRX0155 | B2: 45393 | C2: CUST023 | D2: Paul Baker | E2: P009 | F2: Monitor | G2: Electronics | H2: 3 | I2: 249.99 | J2: Cash | K2: Central | L2: Basic | M2: 44425 | N2: 749.97 | O2: =TEXT(Sales_Data[[#This Row],[Date]],"mmm-yyyy") -> Apr-2024 | P2: =YEAR(Sales_Data[[#This Row],[Date]]) -> 2024 | Q2: =TODAY()-M2 -> 1862 | R2: =DATEDIF(M2,TODAY(),"Y") -> 5 | S2: =EOMONTH(B2,0) -> 45412 | T2: =IF(N2>=1000,"High Value","Normal") -> Normal | U2: =NOW() -> 46287.03
A3: TRX0023 | B3: 45396 | C3: CUST013 | D3: Joseph Jackson | E3: P009 | F3: Monitor | G3: Electronics | H3: 3 | I3: 249.99 | J3: Credit Card | K3: Central | L3: Premium | M3: 44575 | N3: 749.97 | O3: =TEXT(Sales_Data[[#This Row],[Date]],"mmm-yyyy") -> Apr-2024 | P3: =YEAR(Sales_Data[[#This Row],[Date]]) -> 2024 | Q3: =TODAY()-M3 -> 1712 | R3: =DATEDIF(M3,TODAY(),"Y") -> 4 | S3: =EOMONTH(B3,0) -> 45412 | T3: =IF(N3>=1000,"High Value","Normal") -> Normal | U3: =NOW() -> 46287.03
A4: TRX0139 | B4: 45399 | C4: CUST021 | D4: Kevin Scott | E4: P005 | F4: Blender | G4: Appliances | H4: 3 | I4: 59.99 | J4: PayPal | K4: South | L4: Standard | M4: 45262 | N4: 179.97 | O4: =TEXT(Sales_Data[[#This Row],[Date]],"mmm-yyyy") -> Apr-2024 | P4: =YEAR(Sales_Data[[#This Row],[Date]]) -> 2024 | Q4: =TODAY()-M4 -> 1025 | R4: =DATEDIF(M4,TODAY(),"Y") -> 2 | S4: =EOMONTH(B4,0) -> 45412 | T4: =IF(N4>=1000,"High Value","Normal") -> Normal | U4: =NOW() -> 46287.03
A5: TRX0043 | B5: 45400 | C5: CUST046 | D5: Kathleen Bennett | E5: P005 | F5: Blender | G5: Appliances | H5: 3 | I5: 59.99 | J5: Cash | K5: North | L5: Premium | M5: 45114 | N5: 179.97 | O5: =TEXT(Sales_Data[[#This Row],[Date]],"mmm-yyyy") -> Apr-2024 | P5: =YEAR(Sales_Data[[#This Row],[Date]]) -> 2024 | Q5: =TODAY()-M5 -> 1173 | R5: =DATEDIF(M5,TODAY(),"Y") -> 3 | S5: =EOMONTH(B5,0) -> 45412 | T5: =IF(N5>=1000,"High Value","Normal") -> Normal | U5: =NOW() -> 46287.03
A6: TRX0212 | B6: 45400 | C6: CUST003 | D6: Michael Brown | E6: P008 | F6: Bookshelf | G6: Furniture | H6: 5 | I6: 149.99 | J6: Credit Card | K6: North | L6: Premium | M6: 45295 | N6: 749.95 | O6: =TEXT(Sales_Data[[#This Row],[Date]],"mmm-yyyy") -> Apr-2024 | P6: =YEAR(Sales_Data[[#This Row],[Date]]) -> 2024 | Q6: =TODAY()-M6 -> 992 | R6: =DATEDIF(M6,TODAY(),"Y") -> 2 | S6: =EOMONTH(B6,0) -> 45412 | T6: =IF(N6>=1000,"High Value","Normal") -> Normal | U6: =NOW() -> 46287.03
A7: TRX0092 | B7: 45403 | C7: CUST024 | D7: Dorothy Nelson | E7: P005 | F7: Blender | G7: Appliances | H7: 2 | I7: 59.99 | J7: Cash | K7: West | L7: Standard | M7: 44746 | N7: 119.98 | O7: =TEXT(Sales_Data[[#This Row],[Date]],"mmm-yyyy") -> Apr-2024 | P7: =YEAR(Sales_Data[[#This Row],[Date]]) -> 2024 | Q7: =TODAY()-M7 -> 1541 | R7: =DATEDIF(M7,TODAY(),"Y") -> 4 | S7: =EOMONTH(B7,0) -> 45412 | T7: =IF(N7>=1000,"High Value","Normal") -> Normal | U7: =NOW() -> 46287.03
A8: TRX0193 | B8: 45403 | C8: CUST024 | D8: Dorothy Nelson | E8: P003 | F8: Headphones | G8: Electronics | H8: 5 | I8: 149.99 | J8: Credit Card | K8: Central | L8: Standard | M8: 44418 | N8: 749.95 | O8: =TEXT(Sales_Data[[#This Row],[Date]],"mmm-yyyy") -> Apr-2024 | P8: =YEAR(Sales_Data[[#This Row],[Date]]) -> 2024 | Q8: =TODAY()-M8 -> 1869 | R8: =DATEDIF(M8,TODAY(),"Y") -> 5 | S8: =EOMONTH(B8,0) -> 45412 | T8: =IF(N8>=1000,"High Value","Normal") -> Normal | U8: =NOW() -> 46287.03
A9: TRX0240 | B9: 45403 | C9: CUST017 | D9: Charles Allen | E9: P005 | F9: Blender | G9: Appliances | H9: 3 | I9: 59.99 | J9: Debit Card | K9: South | L9: Basic | M9: 45007 | N9: 179.97 | O9: =TEXT(Sales_Data[[#This Row],[Date]],"mmm-yyyy") -> Apr-2024 | P9: =YEAR(Sales_Data[[#This Row],[Date]]) -> 2024 | Q9: =TODAY()-M9 -> 1280 | R9: =DATEDIF(M9,TODAY(),"Y") -> 3 | S9: =EOMONTH(B9,0) -> 45412 | T9: =IF(N9>=1000,"High Value","Normal") -> Normal | U9: =NOW() -> 46287.03
A10: TRX0135 | B10: 45405 | C10: CUST009 | D10: Robert Thomas | E10: P001 | F10: Laptop | G10: Electronics | H10: 3 | I10: 899.99 | J10: PayPal | K10: East | L10: Standard | M10: 45299 | N10: 2699.97 | O10: =TEXT(Sales_Data[[#This Row],[Date]],"mmm-yyyy") -> Apr-2024 | P10: =YEAR(Sales_Data[[#This Row],[Date]]) -> 2024 | Q10: =TODAY()-M10 -> 988 | R10: =DATEDIF(M10,TODAY(),"Y") -> 2 | S10: =EOMONTH(B10,0) -> 45412 | T10: =IF(N10>=1000,"High Value","Normal") -> High Value | U10: =NOW() -> 46287.03
A11: TRX0185 | B11: 45408 | C11: CUST026 | D11: Karen Hill | E11: P005 | F11: Blender | G11: Appliances | H11: 3 | I11: 59.99 | J11: Cash | K11: West | L11: Premium | M11: 45207 | N11: 179.97 | O11: =TEXT(Sales_Data[[#This Row],[Date]],"mmm-yyyy") -> Apr-2024 | P11: =YEAR(Sales_Data[[#This Row],[Date]]) -> 2024 | Q11: =TODAY()-M11 -> 1080 | R11: =DATEDIF(M11,TODAY(),"Y") -> 2 | S11: =EOMONTH(B11,0) -> 45412 | T11: =IF(N11>=1000,"High Value","Normal") -> Normal | U11: =NOW() -> 46287.03
A12: TRX0138 | B12: 45408 | C12: CUST022 | D12: Susan Green | E12: P008 | F12: Bookshelf | G12: Furniture | H12: 1 | I12: 149.99 | J12: Credit Card | K12: West | L12: Standard | M12: 45103 | N12: 149.99 | O12: =TEXT(Sales_Data[[#This Row],[Date]],"mmm-yyyy") -> Apr-2024 | P12: =YEAR(Sales_Data[[#This Row],[Date]]) -> 2024 | Q12: =TODAY()-M12 -> 1184 | R12: =DATEDIF(M12,TODAY(),"Y") -> 3 | S12: =EOMONTH(B12,0) -> 45412 | T12: =IF(N12>=1000,"High Value","Normal") -> Normal | U12: =NOW() -> 46287.03
A13: TRX0209 | B13: 45408 | C13: CUST046 | D13: Kathleen Bennett | E13: P008 | F13: Bookshelf | G13: Furniture | H13: 5 | I13: 149.99 | J13: Debit Card | K13: North | L13: Basic | M13: 44830 | N13: 749.95 | O13: =TEXT(Sales_Data[[#This Row],[Date]],"mmm-yyyy") -> Apr-2024 | P13: =YEAR(Sales_Data[[#This Row],[Date]]) -> 2024 | Q13: =TODAY()-M13 -> 1457 | R13: =DATEDIF(M13,TODAY(),"Y") -> 3 | S13: =EOMONTH(B13,0) -> 45412 | T13: =IF(N13>=1000,"High Value","Normal") -> Normal | U13: =NOW() -> 46287.03
... A251: TRX0064 | B251: 45758 | C251: CUST031 | D251: Steven Turner | E251: P010 | F251: Keyboard | G251: Electronics | H251: 3 | I251: 89.99 | J251: Debit Card | K251: North | L251: Premium | M251: 44878 | N251: 269.97 | O251: =TEXT(Sales_Data[[#This Row],[Date]],"mmm-yyyy") -> Apr-2025 | P251: =YEAR(Sales_Data[[#This Row],[Date]]) -> 2025 | Q251: =TODAY()-M251 -> 1409 | R251: =DATEDIF(M251,TODAY(),"Y") -> 3 | S251: =EOMONTH(B251,0) -> 45777 | T251: =IF(N251>=1000,"High Value","Normal") -> Normal | U251: =NOW() -> 46287.03

Sheet Analysis
A1: Customer Transaction Analysis
A4: A | B4: B
A5: Total Revenue | B5: =SUM(Raw_Data!N:N) -> 229192.47
A6: Total Transactions | B6: =COUNTA(Raw_Data!A:A)-1 -> 250
A7: Total Quantity Sold | B7: =SUM(Raw_Data!H:H) -> 753
A8: Average Order Value | B8: =AVERAGE(Raw_Data!N:N) -> 916.76988
A9: Highest Sale | B9: =MAX(Raw_Data!N:N) -> 4499.95
A10: Lowest Sale | B10: =MIN(Raw_Data!N:N) -> 59.99
A11: Total Customers | B11: =COUNTA(Raw_Data!C:C)-1 -> 250
A12: High Value Customers | B12: =COUNTIF(Raw_Data!T:T,"High Value") -> 61
A14: Category | B14: Sales
A15: Electronics | B15: =SUMIF(Raw_Data!G:G,A15,Raw_Data!N:N) -> 171756.05
A16: Appliances | B16: =SUMIF(Raw_Data!G:G,A16,Raw_Data!N:N) -> 8338.74
A17: Furniture | B17: =SUMIF(Raw_Data!G:G,A17,Raw_Data!N:N) -> 49097.68
A19: Region Wise Sales
A20: Region | B20: Sales
A21: North | B21: =SUMIF(Raw_Data!K:K,A21,Raw_Data!N:N) -> 50808.31
A22: South | B22: =SUMIF(Raw_Data!K:K,A22,Raw_Data!N:N) -> 36398.75
A23: East | B23: =SUMIF(Raw_Data!K:K,A23,Raw_Data!N:N) -> 59288.39
A24: West | B24: =SUMIF(Raw_Data!K:K,A24,Raw_Data!N:N) -> 41408.68
A25: Central | B25: =SUMIF(Raw_Data!K:K,A25,Raw_Data!N:N) -> 41288.34
A27: Payment Method Analysis
A28: Payment Method | B28: Sales
A29: Cash | B29: =SUMIF(Raw_Data!J:J,A29,Raw_Data!N:N) -> 57427.79
A30: Credit Card | B30: =SUMIF(Raw_Data!J:J,A30,Raw_Data!N:N) -> 61447.96
A31: Debit Card | B31: =SUMIF(Raw_Data!J:J,A31,Raw_Data!N:N) -> 52118.31
A32: PayPal | B32: =SUMIF(Raw_Data!J:J,A32,Raw_Data!N:N) -> 58198.41
A34: Customer Segment Analysis
A35: Segment | B35: Sales
A36: Basic | B36: =SUMIF(Raw_Data!L:L,A36,Raw_Data!N:N) -> 62177.81
A37: Standard | B37: =SUMIF(Raw_Data!L:L,A37,Raw_Data!N:N) -> 82357.54
A38: Premium | B38: =SUMIF(Raw_Data!L:L,A38,Raw_Data!N:N) -> 84657.12
A41: High Value Customer Analysis
A42: A | B42: B | C42: C
A43: Customer Name | B43: Total Purchase | C43: Status
A44: Paul Baker | B44: =SUMIF(Raw_Data!D:D,A44,Raw_Data!N:N) -> 8309.74 | C44: =IF(B44>=5000,"High Value","Normal") -> High Value
A45: Joseph Jackson | B45: =SUMIF(Raw_Data!D:D,A45,Raw_Data!N:N) -> 6949.84 | C45: =IF(B45>=5000,"High Value","Normal") -> High Value
A46: Kevin Scott | B46: =SUMIF(Raw_Data!D:D,A46,Raw_Data!N:N) -> 3259.87 | C46: =IF(B46>=5000,"High Value","Normal") -> Normal
A47: Kathleen Bennett | B47: =SUMIF(Raw_Data!D:D,A47,Raw_Data!N:N) -> 4309.81 | C47: =IF(B47>=5000,"High Value","Normal") -> Normal
A48: Michael Brown | B48: =SUMIF(Raw_Data!D:D,A48,Raw_Data!N:N) -> 6169.74 | C48: =IF(B48>=5000,"High Value","Normal") -> High Value
...

Sheet Summary_Output
A1: SUMMARY OUTPUT
A3: Regression Statistics
A4: Multiple R | B4: 0.45808036
A5: R Square | B5: 0.20983762
A6: Adjusted R Square | B6: 0.20665148
A7: Standard Error | B7: 919.60715
A8: Observations | B8: 250
A10: ANOVA
B11: df | C11: SS | D11: MS | E11: F | F11: Significance F
A12: Regression | B12: 1 | C12: 55695917 | D12: 55695917 | E12: 65.859537 | F12: 2.2586479e-14
A13: Residual | B13: 248 | C13: 2.0972797e+08 | D13: 845677.32
A14: Total | B14: 249 | C14: 2.6542389e+08
B16: Coefficients | C16: Standard Error | D16: t Stat | E16: P-value | F16: Lower 95% | G16: Upper 95% | H16: Lower 95.0% | I16: Upper 95.0%
A17: Intercept | B17: -148.85465 | C17: 143.61334 | D17: -1.0364959 | E17: 0.3009804 | F17: -431.712 | G17: 134.0027 | H17: -431.712 | I17: 134.0027
A18: Quantity | B18: 353.793 | C18: 43.595323 | D18: 8.1153889 | E18: 2.2586479e-14 | F18: 267.92872 | G18: 439.65729 | H18: 267.92872 | I18: 439.65729
A22: RESIDUAL OUTPUT
A24: Observation | B24: Predicted Total_Amount | C24: Residuals
A25: 1 | B25: 912.52436 | C25: -162.55436
A26: 2 | B26: 912.52436 | C26: -162.55436
A27: 3 | B27: 912.52436 | C27: -732.55436
A28: 4 | B28: 912.52436 | C28: -732.55436
A29: 5 | B29: 1620.1104 | C29: -870.16037
A30: 6 | B30: 558.73136 | C30: -438.75136
A31: 7 | B31: 1620.1104 | C31: -870.16037
A32: 8 | B32: 912.52436 | C32: -732.55436
A33: 9 | B33: 912.52436 | C33: 1787.4456
A34: 10 | B34: 912.52436 | C34: -732.55436
A35: 11 | B35: 204.93836 | C35: -54.948355
A36: 12 | B36: 1620.1104 | C36: -870.16037
... A274: 250 | B274: 912.52436 | C274: -642.55436

Sheet Pivot_Report
A1: Pivot Reports - Customer Transaction Analysis
A3: Pivot Table 1 – Region Wise Sales | E3: Pivot Table 3 – Product Wise Quantity Sold | I3: Pivot Table 5 – Customer Segment
A4: Region | B4: Total Sales | E4: Product_Name | F4: Quantity Sold | I4: Customer_Segment | J4: Total_Sales
A5: Central | B5: 41288.34 | E5: Bookshelf | F5: 102 | I5: Basic | J5: 62177.81
A6: East | B6: 59288.39 | E6: Smartphone | F6: 96 | I6: Premium | J6: 84657.12
A7: North | B7: 50808.31 | E7: Keyboard | F7: 89 | I7: Standard | J7: 82357.54
A8: South | B8: 36398.75 | E8: Monitor | F8: 88
A9: West | B9: 41408.68 | E9: Blender | F9: 87
E10: Desk | F10: 78
E11: Laptop | F11: 75
E12: Office Chair | F12: 52
E13: Headphones | F13: 47
A14: Pivot Table 2 – Category Wise Sales | E14: Coffee Maker | F14: 39 | I14: Pivot Table 6 – Monthly Sales Trend
A15: Category | B15: Revenue | I15: Month | J15: Total Sales
A16: Appliances | B16: 8338.74 | I16: Apr-2024 | J16: 20919.33
A17: Electronics | B17: 171756.05 | E17: Pivot Table 4 – Payment Method Analysis | I17: Apr-2025 | J17: 6979.83
A18: Furniture | B18: 49097.68 | E18: Payment_Method | F18: Total Sales | I18: Aug-2024 | J18: 15759.43
E19: Cash | F19: 57427.79 | I19: Dec-2024 | J19: 23039.3
E20: Credit Card | F20: 61447.96 | I20: Feb-2025 | J20: 16069.38
E21: Debit Card | F21: 52118.31 | I21: Jan-2025 | J21: 25799.15
E22: PayPal | F22: 58198.41 | I22: Jul-2024 | J22: 18479.4
I23: Jun-2024 | J23: 19299.45
A24: Pivot Table 7 – High Value Customer | I24: Mar-2025 | J24: 19899.38
A25: Customer_Name | B25: Total Sales | I25: May-2024 | J25: 17039.35
A26: Mark Carter | B26: 15659.65 | I26: Nov-2024 | J26: 12309.44
A27: Edward Mitchell | B27: 11919.77 | I27: Oct-2024 | J27: 20609.52
A28: Barbara Young | B28: 10649.8 | I28: Sep-2024 | J28: 12989.51
A29: Patricia Moore | B29: 9799.73 | E29: Pivot Table 8 – Customer Count by Region
A30: Paul Baker | B30: 8309.74 | E30: Region | F30: Count of Customer_ID
A31: Dorothy Nelson | B31: 8269.79 | E31: Central | F31: 54
A32: Karen Hill | B32: 8009.77 | E32: East | F32: 48
A33: Daniel King | B33: 7309.8 | E33: North | F33: 59 | I33: Pivot Table 9 – Product Count
A34: Lawrence Reed | B34: 6989.77 | E34: South | F34: 42 | I34: Product_Name | J34: Count of Transaction_ID
A35: Joseph Jackson | B35: 6949.84 | E35: West | F35: 47 | I35: Blender | J35: 29
A36: Helen Roberts | B36: 6459.79 | I36: Bookshelf | J36: 35
A37: Gerald Murphy | B37: 6379.87 | I37: Coffee Maker | J37: 14
A38: Sandra Phillips | B38: 6349.83 | I38: Desk | J38: 26
A39: Michael Brown | B39: 6169.74 | I39: Headphones | J39: 16
A40: Peter Richardson | B40: 5949.85 | I40: Keyboard | J40: 34
A41: Betty Campbell | B41: 5649.84 | I41: Laptop | J41: 24
...

Sheet Dashboard
A1: CUSTOMER TRANSACTION DASHBOARD
B4: Total Revenue
B5: =Analysis!B5 -> 229192.47
B7: Transactions
B8: =Analysis!B6 -> 250
B10: Quantity Sold
B11: =Analysis!B7 -> 753
B13: Average Order
B14: =Analysis!B8 -> 916.76988
B16: High Value Customers
B17: =Analysis!B12 -> 61
